Workbook

Sheet Configuração
B2: CONFIGURAÇÃO
B4: Cargo | C4: Valor da Diária (R$)
B5: Motorista | C5: 250
B6: Ajudante | C6: 150
B8: Como usar
B9: 1. Preencha os valores das diárias acima (células amarelas).
B10: 2. Na aba 'Registro Diário', lance os funcionários e os dias trabalhados.
B11: 3. A aba 'Resumo Mensal' calcula automaticamente o total de cada um.
B12: 4. Use os filtros para visualizar por cargo ou funcionário.
B13: 5. Os campos de cargo têm dropdown — basta selecionar.

Sheet Registro Diário
A1: REGISTRO DIÁRIO DE FUNCIONÁRIOS
A2: Mês/Ano:
A4: Nº | B4: Data | C4: Funcionário | D4: Cargo | E4: Valor Diária | F4: Observação
A5: 1 | E5: =IF(D5="","",VLOOKUP(D5,Configuração!B5:C6,2,FALSE))
A6: 2 | E6: =IF(D6="","",VLOOKUP(D6,Configuração!B5:C6,2,FALSE))
A7: 3 | E7: =IF(D7="","",VLOOKUP(D7,Configuração!B5:C6,2,FALSE))
A8: 4 | E8: =IF(D8="","",VLOOKUP(D8,Configuração!B5:C6,2,FALSE))
A9: 5 | E9: =IF(D9="","",VLOOKUP(D9,Configuração!B5:C6,2,FALSE))
A10: 6 | E10: =IF(D10="","",VLOOKUP(D10,Configuração!B5:C6,2,FALSE))
A11: 7 | E11: =IF(D11="","",VLOOKUP(D11,Configuração!B5:C6,2,FALSE))
A12: 8 | E12: =IF(D12="","",VLOOKUP(D12,Configuração!B5:C6,2,FALSE))
A13: 9 | E13: =IF(D13="","",VLOOKUP(D13,Configuração!B5:C6,2,FALSE))
A14: 10 | E14: =IF(D14="","",VLOOKUP(D14,Configuração!B5:C6,2,FALSE))
A15: 11 | E15: =IF(D15="","",VLOOKUP(D15,Configuração!B5:C6,2,FALSE))
A16: 12 | E16: =IF(D16="","",VLOOKUP(D16,Configuração!B5:C6,2,FALSE))
A17: 13 | E17: =IF(D17="","",VLOOKUP(D17,Configuração!B5:C6,2,FALSE))
A18: 14 | E18: =IF(D18="","",VLOOKUP(D18,Configuração!B5:C6,2,FALSE))
A19: 15 | E19: =IF(D19="","",VLOOKUP(D19,Configuração!B5:C6,2,FALSE))
A20: 16 | E20: =IF(D20="","",VLOOKUP(D20,Configuração!B5:C6,2,FALSE))
A21: 17 | E21: =IF(D21="","",VLOOKUP(D21,Configuração!B5:C6,2,FALSE))
A22: 18 | E22: =IF(D22="","",VLOOKUP(D22,Configuração!B5:C6,2,FALSE))
A23: 19 | E23: =IF(D23="","",VLOOKUP(D23,Configuração!B5:C6,2,FALSE))
A24: 20 | E24: =IF(D24="","",VLOOKUP(D24,Configuração!B5:C6,2,FALSE))
A25: 21 | E25: =IF(D25="","",VLOOKUP(D25,Configuração!B5:C6,2,FALSE))
A26: 22 | E26: =IF(D26="","",VLOOKUP(D26,Configuração!B5:C6,2,FALSE))
A27: 23 | E27: =IF(D27="","",VLOOKUP(D27,Configuração!B5:C6,2,FALSE))
A28: 24 | E28: =IF(D28="","",VLOOKUP(D28,Configuração!B5:C6,2,FALSE))
A29: 25 | E29: =IF(D29="","",VLOOKUP(D29,Configuração!B5:C6,2,FALSE))
A30: 26 | E30: =IF(D30="","",VLOOKUP(D30,Configuração!B5:C6,2,FALSE))
A31: 27 | E31: =IF(D31="","",VLOOKUP(D31,Configuração!B5:C6,2,FALSE))
A32: 28 | E32: =IF(D32="","",VLOOKUP(D32,Configuração!B5:C6,2,FALSE))
A33: 29 | E33: =IF(D33="","",VLOOKUP(D33,Configuração!B5:C6,2,FALSE))
A34: 30 | E34: =IF(D34="","",VLOOKUP(D34,Configuração!B5:C6,2,FALSE))
A35: 31 | E35: =IF(D35="","",VLOOKUP(D35,Configuração!B5:C6,2,FALSE))
A36: 32 | E36: =IF(D36="","",VLOOKUP(D36,Configuração!B5:C6,2,FALSE))
A37: 33 | E37: =IF(D37="","",VLOOKUP(D37,Configuração!B5:C6,2,FALSE))
A38: 34 | E38: =IF(D38="","",VLOOKUP(D38,Configuração!B5:C6,2,FALSE))
A39: 35 | E39: =IF(D39="","",VLOOKUP(D39,Configuração!B5:C6,2,FALSE))
A40: 36 | E40: =IF(D40="","",VLOOKUP(D40,Configuração!B5:C6,2,FALSE))
A41: 37 | E41: =IF(D41="","",VLOOKUP(D41,Configuração!B5:C6,2,FALSE))
...

Sheet Resumo Mensal
A1: RESUMO MENSAL — PAGAMENTO POR FUNCIONÁRIO
A2: Mês/Ano: | C2: ='Registro Diário'!C2
A4: Nº | B4: Funcionário | C4: Cargo | D4: Dias Trabalhados | E4: Valor Diária | F4: Total a Receber
A5: 1 | D5: =IF(B5="","",COUNTIFS('Registro Diário'!C$5:C$204,B5,'Registro Diário'!D$5:D$204,C5)) | E5: =IF(C5="","",VLOOKUP(C5,Configuração!B5:C6,2,FALSE)) | F5: =IF(B5="","",D5*E5)
A6: 2 | D6: =IF(B6="","",COUNTIFS('Registro Diário'!C$5:C$204,B6,'Registro Diário'!D$5:D$204,C6)) | E6: =IF(C6="","",VLOOKUP(C6,Configuração!B5:C6,2,FALSE)) | F6: =IF(B6="","",D6*E6)
A7: 3 | D7: =IF(B7="","",COUNTIFS('Registro Diário'!C$5:C$204,B7,'Registro Diário'!D$5:D$204,C7)) | E7: =IF(C7="","",VLOOKUP(C7,Configuração!B5:C6,2,FALSE)) | F7: =IF(B7="","",D7*E7)
A8: 4 | D8: =IF(B8="","",COUNTIFS('Registro Diário'!C$5:C$204,B8,'Registro Diário'!D$5:D$204,C8)) | E8: =IF(C8="","",VLOOKUP(C8,Configuração!B5:C6,2,FALSE)) | F8: =IF(B8="","",D8*E8)
A9: 5 | D9: =IF(B9="","",COUNTIFS('Registro Diário'!C$5:C$204,B9,'Registro Diário'!D$5:D$204,C9)) | E9: =IF(C9="","",VLOOKUP(C9,Configuração!B5:C6,2,FALSE)) | F9: =IF(B9="","",D9*E9)
A10: 6 | D10: =IF(B10="","",COUNTIFS('Registro Diário'!C$5:C$204,B10,'Registro Diário'!D$5:D$204,C10)) | E10: =IF(C10="","",VLOOKUP(C10,Configuração!B5:C6,2,FALSE)) | F10: =IF(B10="","",D10*E10)
A11: 7 | D11: =IF(B11="","",COUNTIFS('Registro Diário'!C$5:C$204,B11,'Registro Diário'!D$5:D$204,C11)) | E11: =IF(C11="","",VLOOKUP(C11,Configuração!B5:C6,2,FALSE)) | F11: =IF(B11="","",D11*E11)
A12: 8 | D12: =IF(B12="","",COUNTIFS('Registro Diário'!C$5:C$204,B12,'Registro Diário'!D$5:D$204,C12)) | E12: =IF(C12="","",VLOOKUP(C12,Configuração!B5:C6,2,FALSE)) | F12: =IF(B12="","",D12*E12)
A13: 9 | D13: =IF(B13="","",COUNTIFS('Registro Diário'!C$5:C$204,B13,'Registro Diário'!D$5:D$204,C13)) | E13: =IF(C13="","",VLOOKUP(C13,Configuração!B5:C6,2,FALSE)) | F13: =IF(B13="","",D13*E13)
A14: 10 | D14: =IF(B14="","",COUNTIFS('Registro Diário'!C$5:C$204,B14,'Registro Diário'!D$5:D$204,C14)) | E14: =IF(C14="","",VLOOKUP(C14,Configuração!B5:C6,2,FALSE)) | F14: =IF(B14="","",D14*E14)
A15: 11 | D15: =IF(B15="","",COUNTIFS('Registro Diário'!C$5:C$204,B15,'Registro Diário'!D$5:D$204,C15)) | E15: =IF(C15="","",VLOOKUP(C15,Configuração!B5:C6,2,FALSE)) | F15: =IF(B15="","",D15*E15)
A16: 12 | D16: =IF(B16="","",COUNTIFS('Registro Diário'!C$5:C$204,B16,'Registro Diário'!D$5:D$204,C16)) | E16: =IF(C16="","",VLOOKUP(C16,Configuração!B5:C6,2,FALSE)) | F16: =IF(B16="","",D16*E16)
A17: 13 | D17: =IF(B17="","",COUNTIFS('Registro Diário'!C$5:C$204,B17,'Registro Diário'!D$5:D$204,C17)) | E17: =IF(C17="","",VLOOKUP(C17,Configuração!B5:C6,2,FALSE)) | F17: =IF(B17="","",D17*E17)
A18: 14 | D18: =IF(B18="","",COUNTIFS('Registro Diário'!C$5:C$204,B18,'Registro Diário'!D$5:D$204,C18)) | E18: =IF(C18="","",VLOOKUP(C18,Configuração!B5:C6,2,FALSE)) | F18: =IF(B18="","",D18*E18)
A19: 15 | D19: =IF(B19="","",COUNTIFS('Registro Diário'!C$5:C$204,B19,'Registro Diário'!D$5:D$204,C19)) | E19: =IF(C19="","",VLOOKUP(C19,Configuração!B5:C6,2,FALSE)) | F19: =IF(B19="","",D19*E19)
A20: 16 | D20: =IF(B20="","",COUNTIFS('Registro Diário'!C$5:C$204,B20,'Registro Diário'!D$5:D$204,C20)) | E20: =IF(C20="","",VLOOKUP(C20,Configuração!B5:C6,2,FALSE)) | F20: =IF(B20="","",D20*E20)
A21: 17 | D21: =IF(B21="","",COUNTIFS('Registro Diário'!C$5:C$204,B21,'Registro Diário'!D$5:D$204,C21)) | E21: =IF(C21="","",VLOOKUP(C21,Configuração!B5:C6,2,FALSE)) | F21: =IF(B21="","",D21*E21)
A22: 18 | D22: =IF(B22="","",COUNTIFS('Registro Diário'!C$5:C$204,B22,'Registro Diário'!D$5:D$204,C22)) | E22: =IF(C22="","",VLOOKUP(C22,Configuração!B5:C6,2,FALSE)) | F22: =IF(B22="","",D22*E22)
A23: 19 | D23: =IF(B23="","",COUNTIFS('Registro Diário'!C$5:C$204,B23,'Registro Diário'!D$5:D$204,C23)) | E23: =IF(C23="","",VLOOKUP(C23,Configuração!B5:C6,2,FALSE)) | F23: =IF(B23="","",D23*E23)
A24: 20 | D24: =IF(B24="","",COUNTIFS('Registro Diário'!C$5:C$204,B24,'Registro Diário'!D$5:D$204,C24)) | E24: =IF(C24="","",VLOOKUP(C24,Configuração!B5:C6,2,FALSE)) | F24: =IF(B24="","",D24*E24)
A25: 21 | D25: =IF(B25="","",COUNTIFS('Registro Diário'!C$5:C$204,B25,'Registro Diário'!D$5:D$204,C25)) | E25: =IF(C25="","",VLOOKUP(C25,Configuração!B5:C6,2,FALSE)) | F25: =IF(B25="","",D25*E25)
A26: 22 | D26: =IF(B26="","",COUNTIFS('Registro Diário'!C$5:C$204,B26,'Registro Diário'!D$5:D$204,C26)) | E26: =IF(C26="","",VLOOKUP(C26,Configuração!B5:C6,2,FALSE)) | F26: =IF(B26="","",D26*E26)
A27: 23 | D27: =IF(B27="","",COUNTIFS('Registro Diário'!C$5:C$204,B27,'Registro Diário'!D$5:D$204,C27)) | E27: =IF(C27="","",VLOOKUP(C27,Configuração!B5:C6,2,FALSE)) | F27: =IF(B27="","",D27*E27)
A28: 24 | D28: =IF(B28="","",COUNTIFS('Registro Diário'!C$5:C$204,B28,'Registro Diário'!D$5:D$204,C28)) | E28: =IF(C28="","",VLOOKUP(C28,Configuração!B5:C6,2,FALSE)) | F28: =IF(B28="","",D28*E28)
A29: 25 | D29: =IF(B29="","",COUNTIFS('Registro Diário'!C$5:C$204,B29,'Registro Diário'!D$5:D$204,C29)) | E29: =IF(C29="","",VLOOKUP(C29,Configuração!B5:C6,2,FALSE)) | F29: =IF(B29="","",D29*E29)
A30: 26 | D30: =IF(B30="","",COUNTIFS('Registro Diário'!C$5:C$204,B30,'Registro Diário'!D$5:D$204,C30)) | E30: =IF(C30="","",VLOOKUP(C30,Configuração!B5:C6,2,FALSE)) | F30: =IF(B30="","",D30*E30)
A31: 27 | D31: =IF(B31="","",COUNTIFS('Registro Diário'!C$5:C$204,B31,'Registro Diário'!D$5:D$204,C31)) | E31: =IF(C31="","",VLOOKUP(C31,Configuração!B5:C6,2,FALSE)) | F31: =IF(B31="","",D31*E31)
A32: 28 | D32: =IF(B32="","",COUNTIFS('Registro Diário'!C$5:C$204,B32,'Registro Diário'!D$5:D$204,C32)) | E32: =IF(C32="","",VLOOKUP(C32,Configuração!B5:C6,2,FALSE)) | F32: =IF(B32="","",D32*E32)
A33: 29 | D33: =IF(B33="","",COUNTIFS('Registro Diário'!C$5:C$204,B33,'Registro Diário'!D$5:D$204,C33)) | E33: =IF(C33="","",VLOOKUP(C33,Configuração!B5:C6,2,FALSE)) | F33: =IF(B33="","",D33*E33)
A34: 30 | D34: =IF(B34="","",COUNTIFS('Registro Diário'!C$5:C$204,B34,'Registro Diário'!D$5:D$204,C34)) | E34: =IF(C34="","",VLOOKUP(C34,Configuração!B5:C6,2,FALSE)) | F34: =IF(B34="","",D34*E34)
A35: 31 | D35: =IF(B35="","",COUNTIFS('Registro Diário'!C$5:C$204,B35,'Registro Diário'!D$5:D$204,C35)) | E35: =IF(C35="","",VLOOKUP(C35,Configuração!B5:C6,2,FALSE)) | F35: =IF(B35="","",D35*E35)
A36: 32 | D36: =IF(B36="","",COUNTIFS('Registro Diário'!C$5:C$204,B36,'Registro Diário'!D$5:D$204,C36)) | E36: =IF(C36="","",VLOOKUP(C36,Configuração!B5:C6,2,FALSE)) | F36: =IF(B36="","",D36*E36)
A37: 33 | D37: =IF(B37="","",COUNTIFS('Registro Diário'!C$5:C$204,B37,'Registro Diário'!D$5:D$204,C37)) | E37: =IF(C37="","",VLOOKUP(C37,Configuração!B5:C6,2,FALSE)) | F37: =IF(B37="","",D37*E37)
A38: 34 | D38: =IF(B38="","",COUNTIFS('Registro Diário'!C$5:C$204,B38,'Registro Diário'!D$5:D$204,C38)) | E38: =IF(C38="","",VLOOKUP(C38,Configuração!B5:C6,2,FALSE)) | F38: =IF(B38="","",D38*E38)
A39: 35 | D39: =IF(B39="","",COUNTIFS('Registro Diário'!C$5:C$204,B39,'Registro Diário'!D$5:D$204,C39)) | E39: =IF(C39="","",VLOOKUP(C39,Configuração!B5:C6,2,FALSE)) | F39: =IF(B39="","",D39*E39)
A40: 36 | D40: =IF(B40="","",COUNTIFS('Registro Diário'!C$5:C$204,B40,'Registro Diário'!D$5:D$204,C40)) | E40: =IF(C40="","",VLOOKUP(C40,Configuração!B5:C6,2,FALSE)) | F40: =IF(B40="","",D40*E40)
A41: 37 | D41: =IF(B41="","",COUNTIFS('Registro Diário'!C$5:C$204,B41,'Registro Diário'!D$5:D$204,C41)) | E41: =IF(C41="","",VLOOKUP(C41,Configuração!B5:C6,2,FALSE)) | F41: =IF(B41="","",D41*E41)
...
